Workbook

Sheet Visualization
A1: Date | B1: Litre
A2: 45292 | B2: 2.250526
A3: 45293 | B3: 2.1550271
A4: 45294 | B4: 2.2006895
A5: 45295 | B5: 2.1085771
A6: 45296 | B6: 2.2832906
A7: 45297 | B7: 1.6966565
A8: 45298 | B8: 1.6188466
A9: 45299 | B9: 2.2397975
A10: 45300 | B10: 2.2667257
A11: 45301 | B11: 2.2791504
A12: 45302 | B12: 2.2706708
A13: 45303 | B13: 2.2233255
... A50: 45340 | B50: 1.5329352

Sheet Progress Summary
A2: Study Hours
A3: Day Count | B3: Total Available | C3: =COUNTA('Study Hours Data'!A:A)-1 -> 58
B4: Elapsed | C4: =COUNT('Study Hours Data'!B:B)-1 -> 8
B5: Remaining | C5: =C3-C4 -> 50
A6: Study Hours | B6: Actual (Total hours studied till now) | C6: =SUM('Study Hours Data'!B2:B1048576) -> 30
B7: Deficit (Hours to cover up) | C7: =IF(((C4*'Goals Data'!B5)-C6)<=0,0,(C4*'Goals Data'!B5)-C6) -> 0
B8: Expected (Total hours that should have been done) | C8: =C4*'Goals Data'!B5 -> 20.689655
A9: Daily Average | B9: Current | C9: =C6/C4 -> 3.75
B10: Updated | C10: =('Goals Data'!B3-C6)/C5 -> 2.4
A11: Projections | B11: Total hours I'll complete at this rate (by module end) | C11: =('Goals Data'!B4*C6)/C4 -> 217.5
A12: Current Status | B12: {=_xlfn.IFS(C10='Goals Data'!B5,"You're on track!",C10>'Goals Data'!B5,"At this rate, you'll have to spend "&ROUND(C10,2)&" hours daily! 😭",C10<'Goals Data'!B5,"Great stuff! Keep going.")} -> Great stuff! Keep going.
A13: Data Competency: Excel
A15: Overall | B15: Coverage | C15: =COUNTA('Excel Syllabus Data'!D2:D102)/COUNTA('Excel Syllabus Data'!C2:C102) -> 0.11881188
B16: Mastery | C16: =IF(SUM('Excel Syllabus Data'!E2:E102)=0,0,SUM('Excel Syllabus Data'!E2:E102)/(100*COUNT('Excel Syllabus Data'!E2:E102))) -> 0.41666667
B17: Rank | C17: =IF(C16="","Uninitiated",VLOOKUP(C16,'Goals Data'!$A$15:$B$18,2,1)) -> Rookie
A19: Skill Wise Breakdown
A20: Data Gathering | B20: Coverage | C20: =COUNTA('Excel Syllabus Data'!D5:D13)/COUNTA('Excel Syllabus Data'!C5:C13) -> 1
B21: Mastery | C21: =IF(SUM('Excel Syllabus Data'!E2:E102)=0,0,SUM('Excel Syllabus Data'!E5:E13)/(100*COUNT('Excel Syllabus Data'!E5:E13))) -> 0.41666667
B22: Rank | C22: =IF(C21="","Uninitiated",VLOOKUP(C21,'Goals Data'!$A$15:$B$18,2,1)) -> Rookie
A23: Data Preparation | B23: Coverage | C23: =COUNTA('Excel Syllabus Data'!D14:D38)/COUNTA('Excel Syllabus Data'!C14:C38) -> 0
B24: Mastery | C24: =IF(SUM('Excel Syllabus Data'!E14:E38) = 0, 0, SUM('Excel Syllabus Data'!E14:E38)/(100*COUNT('Excel Syllabus Data'!E14:E38))) -> 0
B25: Rank | C25: =IF(C24="","Uninitiated",VLOOKUP(C24,'Goals Data'!$A$15:$B$18,2,1)) -> Uninitiated
A26: Data Analysis | B26: Coverage | C26: =COUNTA('Excel Syllabus Data'!D39:D88)/COUNTA('Excel Syllabus Data'!C39:C88) -> 0
B27: Mastery | C27: =IF(SUM('Excel Syllabus Data'!E39:E88) = 0, 0, SUM('Excel Syllabus Data'!E39:E88)/(100*COUNT('Excel Syllabus Data'!E39:E88))) -> 0
B28: Rank | C28: =IF(C27="","Uninitiated",VLOOKUP(C27,'Goals Data'!$A$15:$B$18,2,1)) -> Uninitiated
A29: Data Visualization | B29: Coverage | C29: =COUNTA('Excel Syllabus Data'!D89:D102)/COUNTA('Excel Syllabus Data'!C89:C102) -> 0
B30: Mastery | C30: =IF(SUM('Excel Syllabus Data'!E89:E102) = 0,0,SUM('Excel Syllabus Data'!E89:E102)/(100*COUNT('Excel Syllabus Data'!E89:E102))) -> 0
B31: Rank | C31: =IF(C30="","Uninitiated",VLOOKUP(C30,'Goals Data'!$A$15:$B$18,2,1)) -> Uninitiated
A33: Day Level Average
A34: Day | B34: Total Study Hours | C34: No of Day Elapsed | D34: Average Study Hours
A35: Monday | B35: =SUMIFS('Study Hours Data'!$B:$B,'Study Hours Data'!$E:$E,'Progress Summary'!A35) -> 2 | C35: =COUNTIFS('Study Hours Data'!$E:$E,'Progress Summary'!A35) -> 2 | D35: =B35/C35 -> 1
A36: Tuesday | B36: =SUMIFS('Study Hours Data'!$B:$B,'Study Hours Data'!$E:$E,'Progress Summary'!A36) -> 2 | C36: =COUNTIFS('Study Hours Data'!$E:$E,'Progress Summary'!A36) -> 1 | D36: =B36/C36 -> 2
A37: Wednesday | B37: =SUMIFS('Study Hours Data'!$B:$B,'Study Hours Data'!$E:$E,'Progress Summary'!A37) -> 2 | C37: =COUNTIFS('Study Hours Data'!$E:$E,'Progress Summary'!A37) -> 1 | D37: =B37/C37 -> 2
A38: Thursday | B38: =SUMIFS('Study Hours Data'!$B:$B,'Study Hours Data'!$E:$E,'Progress Summary'!A38) -> 2 | C38: =COUNTIFS('Study Hours Data'!$E:$E,'Progress Summary'!A38) -> 1 | D38: =B38/C38 -> 2
A39: Friday | B39: =SUMIFS('Study Hours Data'!$B:$B,'Study Hours Data'!$E:$E,'Progress Summary'!A39) -> 2 | C39: =COUNTIFS('Study Hours Data'!$E:$E,'Progress Summary'!A39) -> 1 | D39: =B39/C39 -> 2
A40: Saturday | B40: =SUMIFS('Study Hours Data'!$B:$B,'Study Hours Data'!$E:$E,'Progress Summary'!A40) -> 10 | C40: =COUNTIFS('Study Hours Data'!$E:$E,'Progress Summary'!A40) -> 2 | D40: =B40/C40 -> 5
A41: Sunday | B41: =SUMIFS('Study Hours Data'!$B:$B,'Study Hours Data'!$E:$E,'Progress Summary'!A41) -> 10 | C41: =COUNTIFS('Study Hours Data'!$E:$E,'Progress Summary'!A41) -> 2 | D41: =B41/C41 -> 5

Sheet Progress Dashboard

Sheet Goals Data
A2: Study Goal
A3: Target Hours | B3: 150
A4: Available Days | B4: =COUNT('Study Hours Data'!A:A) -> 58
A5: Daily Goal Hours | B5: =B3/B4 -> 2.5862069
A8: Level of Understanding | B8: Score
A9: Low | B9: 25
A10: Medium | B10: 50
A11: High | B11: 100
A14: Rank | B14: Score
A15: 0 | B15: Uninitiated
A16: 0.25 | B16: Rookie
A17: 0.5 | B17: Skilled
A18: 0.9 | B18: Professional
A19: 1 | B19: Legendary

Sheet Excel Syllabus Data
A1: Category | B1: Topic | C1: Concepts | D1: Level of Understanding | E1: Score
A2: Intro to Excel | B2: Excel for Analytics | C2: Excels' role in each of the analysis stages | D2: Medium | E2: =IFERROR(VLOOKUP(D2,'Goals Data'!$A$8:$B$11,2,0),"") -> 50
B3: Excel terminologies | C3: Workbook, worksheets, rows, columns, cells, and ranges | D3: Medium | E3: =IFERROR(VLOOKUP(D3,'Goals Data'!$A$8:$B$11,2,0),"") -> 50
B4: Excel Shortcut Keys | C4: Commonly used shortcut keys | D4: Low | E4: =IFERROR(VLOOKUP(D4,'Goals Data'!$A$8:$B$11,2,0),"") -> 25
A5: Data Gathering | B5: Structured Data | C5: What is structured data? | D5: Medium | E5: =IFERROR(VLOOKUP(D5,'Goals Data'!$A$8:$B$11,2,0),"") -> 50
B6: Importing Data | C6: Using Get data feature | D6: Medium | E6: =IFERROR(VLOOKUP(D6,'Goals Data'!$A$8:$B$11,2,0),"") -> 50
C7: Handling JSON | D7: Low | E7: =IFERROR(VLOOKUP(D7,'Goals Data'!$A$8:$B$11,2,0),"") -> 25
B8: Data Types | C8: Text/String, Number, Date, Boolean, Error | D8: Medium | E8: =IFERROR(VLOOKUP(D8,'Goals Data'!$A$8:$B$11,2,0),"") -> 50
B9: Data Validation | C9: Restricting data entries for data correctness | D9: Medium | E9: =IFERROR(VLOOKUP(D9,'Goals Data'!$A$8:$B$11,2,0),"") -> 50
C10: Custom data validations | D10: Low | E10: =IFERROR(VLOOKUP(D10,'Goals Data'!$A$8:$B$11,2,0),"") -> 25
C11: Remove Duplicates (Dealing with Duplicates) | D11: Medium | E11: =IFERROR(VLOOKUP(D11,'Goals Data'!$A$8:$B$11,2,0),"") -> 50
C12: Transpose | D12: Medium | E12: =IFERROR(VLOOKUP(D12,'Goals Data'!$A$8:$B$11,2,0),"") -> 50
C13: Text to Columns | D13: Low | E13: =IFERROR(VLOOKUP(D13,'Goals Data'!$A$8:$B$11,2,0),"") -> 25
A14: Data Preparation | B14: Formatting | C14: What is formatting? | E14: =IFERROR(VLOOKUP(D14,'Goals Data'!$A$8:$B$11,2,0),"")
C15: Various formatting options (Text Font, Text Alignment etc..) | E15: =IFERROR(VLOOKUP(D15,'Goals Data'!$A$8:$B$11,2,0),"")
C16: Number formatting | E16: =IFERROR(VLOOKUP(D16,'Goals Data'!$A$8:$B$11,2,0),"")
C17: Custom number formats | E17: =IFERROR(VLOOKUP(D17,'Goals Data'!$A$8:$B$11,2,0),"")
C18: Date & Time Formatting | E18: =IFERROR(VLOOKUP(D18,'Goals Data'!$A$8:$B$11,2,0),"")
C19: Custom Date & Time formats | E19: =IFERROR(VLOOKUP(D19,'Goals Data'!$A$8:$B$11,2,0),"")
C20: Grouping-UnGrouping | E20: =IFERROR(VLOOKUP(D20,'Goals Data'!$A$8:$B$11,2,0),"")
B21: Conditional Formatting | C21: Basic conditional formatting options | E21: =IFERROR(VLOOKUP(D21,'Goals Data'!$A$8:$B$11,2,0),"")
C22: Custom conditional formatting | E22: =IFERROR(VLOOKUP(D22,'Goals Data'!$A$8:$B$11,2,0),"")
B23: Paste Special | C23: Copy-paste-paste special | E23: =IFERROR(VLOOKUP(D23,'Goals Data'!$A$8:$B$11,2,0),"")
B24: Sort and Filter | C24: Quick sort | E24: =IFERROR(VLOOKUP(D24,'Goals Data'!$A$8:$B$11,2,0),"")
C25: Custom sort | E25: =IFERROR(VLOOKUP(D25,'Goals Data'!$A$8:$B$11,2,0),"")
C26: Filters | E26: =IFERROR(VLOOKUP(D26,'Goals Data'!$A$8:$B$11,2,0),"")
B27: Cell References | C27: Relative | E27: =IFERROR(VLOOKUP(D27,'Goals Data'!$A$8:$B$11,2,0),"")
C28: Absolute | E28: =IFERROR(VLOOKUP(D28,'Goals Data'!$A$8:$B$11,2,0),"")
B29: Text / string functions | C29: TEXTBEFORE | E29: =IFERROR(VLOOKUP(D29,'Goals Data'!$A$8:$B$11,2,0),"")
C30: TEXTAFTER | E30: =IFERROR(VLOOKUP(D30,'Goals Data'!$A$8:$B$11,2,0),"")
C31: LEFT | E31: =IFERROR(VLOOKUP(D31,'Goals Data'!$A$8:$B$11,2,0),"")
C32: RIGHT | E32: =IFERROR(VLOOKUP(D32,'Goals Data'!$A$8:$B$11,2,0),"")
C33: MID | E33: =IFERROR(VLOOKUP(D33,'Goals Data'!$A$8:$B$11,2,0),"")
C34: CONCATENATE | E34: =IFERROR(VLOOKUP(D34,'Goals Data'!$A$8:$B$11,2,0),"")
C35: TRIM | E35: =IFERROR(VLOOKUP(D35,'Goals Data'!$A$8:$B$11,2,0),"")
C36: SUBSTITUTE | E36: =IFERROR(VLOOKUP(D36,'Goals Data'!$A$8:$B$11,2,0),"")
C37: VALUE | E37: =IFERROR(VLOOKUP(D37,'Goals Data'!$A$8:$B$11,2,0),"")
C38: TEXT | E38: =IFERROR(VLOOKUP(D38,'Goals Data'!$A$8:$B$11,2,0),"")
A39: Data Analysis | B39: Logical functions | C39: IF | E39: =IFERROR(VLOOKUP(D39,'Goals Data'!$A$8:$B$11,2,0),"")
C40: AND, OR | E40: =IFERROR(VLOOKUP(D40,'Goals Data'!$A$8:$B$11,2,0),"")
...

Sheet Study Hours Data
A1: Date | B1: Hours | C1: Total Hours | D1: Day of the Week | E1: Day Name | F1: Target | N1: Day Number | O1: Day Name
A2: 45521 | B2: 5 | C2: =IF(B2="","",SUM($B$2:B2)) -> 5 | D2: =WEEKDAY(A2,2) -> 6 | E2: =IF(B2="","",VLOOKUP(D2,$N$1:$O$8,2,0)) -> Saturday | F2: ='Goals Data'!$B$3 -> 150 | N2: 1 | O2: Monday
A3: 45522 | B3: 5 | C3: =SUM($B$2:B3) -> 10 | D3: =WEEKDAY(A3,2) -> 7 | E3: =IF(B3="","",VLOOKUP(D3,$N$1:$O$8,2,0)) -> Sunday | F3: ='Goals Data'!$B$3 -> 150 | N3: 2 | O3: Tuesday
A4: 45523 | B4: 2 | C4: =SUM($B$2:B4) -> 12 | D4: =WEEKDAY(A4,2) -> 1 | E4: =IF(B4="","",VLOOKUP(D4,$N$1:$O$8,2,0)) -> Monday | F4: ='Goals Data'!$B$3 -> 150 | N4: 3 | O4: Wednesday
A5: 45524 | B5: 2 | C5: =SUM($B$2:B5) -> 14 | D5: =WEEKDAY(A5,2) -> 2 | E5: =IF(B5="","",VLOOKUP(D5,$N$1:$O$8,2,0)) -> Tuesday | F5: ='Goals Data'!$B$3 -> 150 | N5: 4 | O5: Thursday
A6: 45525 | B6: 2 | C6: =SUM($B$2:B6) -> 16 | D6: =WEEKDAY(A6,2) -> 3 | E6: =IF(B6="","",VLOOKUP(D6,$N$1:$O$8,2,0)) -> Wednesday | F6: ='Goals Data'!$B$3 -> 150 | N6: 5 | O6: Friday
A7: 45526 | B7: 2 | C7: =SUM($B$2:B7) -> 18 | D7: =WEEKDAY(A7,2) -> 4 | E7: =IF(B7="","",VLOOKUP(D7,$N$1:$O$8,2,0)) -> Thursday | F7: ='Goals Data'!$B$3 -> 150 | N7: 6 | O7: Saturday
A8: 45527 | B8: 2 | C8: =SUM($B$2:B8) -> 20 | D8: =WEEKDAY(A8,2) -> 5 | E8: =IF(B8="","",VLOOKUP(D8,$N$1:$O$8,2,0)) -> Friday | F8: ='Goals Data'!$B$3 -> 150 | N8: 7 | O8: Sunday
A9: 45528 | B9: 5 | C9: =SUM($B$2:B9) -> 25 | D9: =WEEKDAY(A9,2) -> 6 | E9: =IF(B9="","",VLOOKUP(D9,$N$1:$O$8,2,0)) -> Saturday | F9: ='Goals Data'!$B$3 -> 150
A10: 45529 | B10: 5 | C10: =SUM($B$2:B10) -> 30 | D10: =WEEKDAY(A10,2) -> 7 | E10: =IF(B10="","",VLOOKUP(D10,$N$1:$O$8,2,0)) -> Sunday | F10: ='Goals Data'!$B$3 -> 150
A11: 45530 | D11: =WEEKDAY(A11,2) -> 1 | E11: =IF(B11="","",VLOOKUP(D11,$N$1:$O$8,2,0)) | F11: ='Goals Data'!$B$3 -> 150
A12: 45531 | D12: =WEEKDAY(A12,2) -> 2 | E12: =IF(B12="","",VLOOKUP(D12,$N$1:$O$8,2,0)) | F12: ='Goals Data'!$B$3 -> 150
A13: 45532 | D13: =WEEKDAY(A13,2) -> 3 | E13: =IF(B13="","",VLOOKUP(D13,$N$1:$O$8,2,0)) | F13: ='Goals Data'!$B$3 -> 150
A14: 45533 | D14: =WEEKDAY(A14,2) -> 4 | E14: =IF(B14="","",VLOOKUP(D14,$N$1:$O$8,2,0)) | F14: ='Goals Data'!$B$3 -> 150
A15: 45534 | D15: =WEEKDAY(A15,2) -> 5 | E15: =IF(B15="","",VLOOKUP(D15,$N$1:$O$8,2,0)) | F15: ='Goals Data'!$B$3 -> 150
A16: 45535 | D16: =WEEKDAY(A16,2) -> 6 | E16: =IF(B16="","",VLOOKUP(D16,$N$1:$O$8,2,0)) | F16: ='Goals Data'!$B$3 -> 150
A17: 45536 | D17: =WEEKDAY(A17,2) -> 7 | E17: =IF(B17="","",VLOOKUP(D17,$N$1:$O$8,2,0)) | F17: ='Goals Data'!$B$3 -> 150
A18: 45537 | D18: =WEEKDAY(A18,2) -> 1 | E18: =VLOOKUP(D18,$N$1:$O$8,2,0) -> Monday | F18: ='Goals Data'!$B$3 -> 150
A19: 45538 | D19: =WEEKDAY(A19,2) -> 2 | E19: =IF(B19="","",VLOOKUP(D19,$N$1:$O$8,2,0)) | F19: ='Goals Data'!$B$3 -> 150
A20: 45539 | D20: =WEEKDAY(A20,2) -> 3 | E20: =IF(B20="","",VLOOKUP(D20,$N$1:$O$8,2,0)) | F20: ='Goals Data'!$B$3 -> 150
A21: 45540 | D21: =WEEKDAY(A21,2) -> 4 | E21: =IF(B21="","",VLOOKUP(D21,$N$1:$O$8,2,0)) | F21: ='Goals Data'!$B$3 -> 150
A22: 45541 | D22: =WEEKDAY(A22,2) -> 5 | E22: =IF(B22="","",VLOOKUP(D22,$N$1:$O$8,2,0)) | F22: ='Goals Data'!$B$3 -> 150
A23: 45542 | D23: =WEEKDAY(A23,2) -> 6 | E23: =IF(B23="","",VLOOKUP(D23,$N$1:$O$8,2,0)) | F23: ='Goals Data'!$B$3 -> 150
A24: 45543 | D24: =WEEKDAY(A24,2) -> 7 | E24: =IF(B24="","",VLOOKUP(D24,$N$1:$O$8,2,0)) | F24: ='Goals Data'!$B$3 -> 150
A25: 45544 | D25: =WEEKDAY(A25,2) -> 1 | E25: =IF(B25="","",VLOOKUP(D25,$N$1:$O$8,2,0)) | F25: ='Goals Data'!$B$3 -> 150
A26: 45545 | D26: =WEEKDAY(A26,2) -> 2 | E26: =IF(B26="","",VLOOKUP(D26,$N$1:$O$8,2,0)) | F26: ='Goals Data'!$B$3 -> 150
A27: 45546 | D27: =WEEKDAY(A27,2) -> 3 | E27: =IF(B27="","",VLOOKUP(D27,$N$1:$O$8,2,0)) | F27: ='Goals Data'!$B$3 -> 150
A28: 45547 | D28: =WEEKDAY(A28,2) -> 4 | E28: =IF(B28="","",VLOOKUP(D28,$N$1:$O$8,2,0)) | F28: ='Goals Data'!$B$3 -> 150
A29: 45548 | D29: =WEEKDAY(A29,2) -> 5 | E29: =IF(B29="","",VLOOKUP(D29,$N$1:$O$8,2,0)) | F29: ='Goals Data'!$B$3 -> 150
A30: 45549 | D30: =WEEKDAY(A30,2) -> 6 | E30: =IF(B30="","",VLOOKUP(D30,$N$1:$O$8,2,0)) | F30: ='Goals Data'!$B$3 -> 150
... A59: 45578 | D59: =WEEKDAY(A59,2) -> 7 | E59: =IF(B59="","",VLOOKUP(D59,$N$1:$O$8,2,0)) | F59: ='Goals Data'!$B$3 -> 150
Q81: 3
